Workbook

Sheet Tracker
A1: Firma | B1: Nische | C1: E-Mail | D1: Status | E1: Erstmail am | F1: Follow-up fällig | G1: Follow-up gesendet am | H1: Antwort am | I1: Antwort | J1: Nächster Schritt | K1: Mail-Datei | L1: Notizen
A2: Jenkins Roofing | B2: Dachdecker | C2: info@jenkinsroofing.com | D2: Follow-up gesendet | E2: 46296 | F2: =IF(OR(E2="",G2<>"",H2<>""),"",WORKDAY(E2,5)) | G2: 46301 | J2: =IF(A2="","",IF(I2<>"","Antwort bearbeiten",IF(G2<>"",IF(TODAY()>=WORKDAY(G2,7),"Als Keine Antwort abschließen","Warten auf Antwort"),IF(E2<>"",IF(TODAY()>=F2,"Follow-up schreiben!","Warten bis Follow-up-Datum"),IF(D2="Versandbereit","Erstmail senden","Konzept fertigstellen"))))) | K2: 03-Versandfertig | L2: Video: Papier-Theater
A3: Evans & Horton Roofing | B3: Dachdecker | C3: info@evansandhorton.com | D3: Follow-up gesendet | E3: 46296 | F3: =IF(OR(E3="",G3<>"",H3<>""),"",WORKDAY(E3,5)) | G3: 46302 | J3: =IF(A3="","",IF(I3<>"","Antwort bearbeiten",IF(G3<>"",IF(TODAY()>=WORKDAY(G3,7),"Als Keine Antwort abschließen","Warten auf Antwort"),IF(E3<>"",IF(TODAY()>=F3,"Follow-up schreiben!","Warten bis Follow-up-Datum"),IF(D3="Versandbereit","Erstmail senden","Konzept fertigstellen"))))) | K3: 03-Versandfertig | L3: Video: Handy-Story 9:16
A4: JCI Roofing | B4: Dachdecker | D4: In Bearbeitung | F4: =IF(OR(E4="",G4<>"",H4<>""),"",WORKDAY(E4,5)) | J4: =IF(A4="","",IF(I4<>"","Antwort bearbeiten",IF(G4<>"",IF(TODAY()>=WORKDAY(G4,7),"Als Keine Antwort abschließen","Warten auf Antwort"),IF(E4<>"",IF(TODAY()>=F4,"Follow-up schreiben!","Warten bis Follow-up-Datum"),IF(D4="Versandbereit","Erstmail senden","Konzept fertigstellen"))))) | K4: 03-Versandfertig | L4: E-Mail-Adresse fehlt
A5: Ft Worth Fence & Patio | B5: Zaun & Terrasse | C5: sales@ftworthfenceandpatio.com | D5: Follow-up gesendet | E5: 46297 | F5: =IF(OR(E5="",G5<>"",H5<>""),"",WORKDAY(E5,5)) | G5: 46301 | J5: =IF(A5="","",IF(I5<>"","Antwort bearbeiten",IF(G5<>"",IF(TODAY()>=WORKDAY(G5,7),"Als Keine Antwort abschließen","Warten auf Antwort"),IF(E5<>"",IF(TODAY()>=F5,"Follow-up schreiben!","Warten bis Follow-up-Datum"),IF(D5="Versandbereit","Erstmail senden","Konzept fertigstellen"))))) | K5: 04-Versandfertig-Bright-Tree-Fence
A6: Bright Tree Service | B6: Baumpflege | C6: info@brighttreeservice.com | D6: Follow-up gesendet | E6: 46297 | F6: =IF(OR(E6="",G6<>"",H6<>""),"",WORKDAY(E6,5)) | G6: 46302 | J6: =IF(A6="","",IF(I6<>"","Antwort bearbeiten",IF(G6<>"",IF(TODAY()>=WORKDAY(G6,7),"Als Keine Antwort abschließen","Warten auf Antwort"),IF(E6<>"",IF(TODAY()>=F6,"Follow-up schreiben!","Warten bis Follow-up-Datum"),IF(D6="Versandbereit","Erstmail senden","Konzept fertigstellen"))))) | K6: 04-Versandfertig-Bright-Tree-Fence
A7: American Air Customs | B7: HVAC | C7: americanaircustoms@yahoo.com | D7: Follow-up gesendet | E7: 46297 | F7: =IF(OR(E7="",G7<>"",H7<>""),"",WORKDAY(E7,5)) | G7: 46302 | J7: =IF(A7="","",IF(I7<>"","Antwort bearbeiten",IF(G7<>"",IF(TODAY()>=WORKDAY(G7,7),"Als Keine Antwort abschließen","Warten auf Antwort"),IF(E7<>"",IF(TODAY()>=F7,"Follow-up schreiben!","Warten bis Follow-up-Datum"),IF(D7="Versandbereit","Erstmail senden","Konzept fertigstellen"))))) | K7: 05-Versandfertig-American-Air-Customs
A8: Kelly's Pool Care | B8: Pool | C8: info@kellyspoolcare.com | D8: Follow-up gesendet | E8: 46298 | F8: =IF(OR(E8="",G8<>"",H8<>""),"",WORKDAY(E8,5)) | G8: 46303 | J8: =IF(A8="","",IF(I8<>"","Antwort bearbeiten",IF(G8<>"",IF(TODAY()>=WORKDAY(G8,7),"Als Keine Antwort abschließen","Warten auf Antwort"),IF(E8<>"",IF(TODAY()>=F8,"Follow-up schreiben!","Warten bis Follow-up-Datum"),IF(D8="Versandbereit","Erstmail senden","Konzept fertigstellen"))))) | K8: 06-Versandfertig-Kellys-Pool-Care
A9: Structured Foundation Repairs | B9: Fundament | C9: info@structuredfoundation.com | D9: Follow-up gesendet | E9: 46300 | F9: =IF(OR(E9="",G9<>"",H9<>""),"",WORKDAY(E9,5)) | G9: 46305 | J9: =IF(A9="","",IF(I9<>"","Antwort bearbeiten",IF(G9<>"",IF(TODAY()>=WORKDAY(G9,7),"Als Keine Antwort abschließen","Warten auf Antwort"),IF(E9<>"",IF(TODAY()>=F9,"Follow-up schreiben!","Warten bis Follow-up-Datum"),IF(D9="Versandbereit","Erstmail senden","Konzept fertigstellen"))))) | K9: 07-Versandfertig-Structured-Foundation | L9: Follow-up 10.10. verschickt
A10: Garland Heating and Air Conditioning | B10: HVAC | C10: info@garlandheatingandair.com | D10: Follow-up gesendet | E10: 46300 | F10: =IF(OR(E10="",G10<>"",H10<>""),"",WORKDAY(E10,5)) | G10: 46305 | J10: =IF(A10="","",IF(I10<>"","Antwort bearbeiten",IF(G10<>"",IF(TODAY()>=WORKDAY(G10,7),"Als Keine Antwort abschließen","Warten auf Antwort"),IF(E10<>"",IF(TODAY()>=F10,"Follow-up schreiben!","Warten bis Follow-up-Datum"),IF(D10="Versandbereit","Erstmail senden","Konzept fertigstellen"))))) | K10: 08-Versandfertig-HVAC | L10: Follow-up 10.10. verschickt
A11: Just Right Air & Heat | B11: HVAC | C11: justrightairheat@gmail.com | D11: Follow-up gesendet | E11: 46300 | F11: =IF(OR(E11="",G11<>"",H11<>""),"",WORKDAY(E11,5)) | G11: 46305 | J11: =IF(A11="","",IF(I11<>"","Antwort bearbeiten",IF(G11<>"",IF(TODAY()>=WORKDAY(G11,7),"Als Keine Antwort abschließen","Warten auf Antwort"),IF(E11<>"",IF(TODAY()>=F11,"Follow-up schreiben!","Warten bis Follow-up-Datum"),IF(D11="Versandbereit","Erstmail senden","Konzept fertigstellen"))))) | K11: 08-Versandfertig-HVAC | L11: Follow-up 10.10. verschickt
A12: A/C Service & Repairs Co. | B12: HVAC | C12: russ@acserviceandrepairs.com | D12: Follow-up gesendet | E12: 46300 | F12: =IF(OR(E12="",G12<>"",H12<>""),"",WORKDAY(E12,5)) | G12: 46305 | J12: =IF(A12="","",IF(I12<>"","Antwort bearbeiten",IF(G12<>"",IF(TODAY()>=WORKDAY(G12,7),"Als Keine Antwort abschließen","Warten auf Antwort"),IF(E12<>"",IF(TODAY()>=F12,"Follow-up schreiben!","Warten bis Follow-up-Datum"),IF(D12="Versandbereit","Erstmail senden","Konzept fertigstellen"))))) | K12: 08-Versandfertig-HVAC | L12: Follow-up 10.10. verschickt
A13: Hector Torres HVAC | B13: HVAC | C13: iraelt@hotmail.com | D13: Follow-up gesendet | E13: 46300 | F13: =IF(OR(E13="",G13<>"",H13<>""),"",WORKDAY(E13,5)) | G13: 46305 | J13: =IF(A13="","",IF(I13<>"","Antwort bearbeiten",IF(G13<>"",IF(TODAY()>=WORKDAY(G13,7),"Als Keine Antwort abschließen","Warten auf Antwort"),IF(E13<>"",IF(TODAY()>=F13,"Follow-up schreiben!","Warten bis Follow-up-Datum"),IF(D13="Versandbereit","Erstmail senden","Konzept fertigstellen"))))) | K13: 08-Versandfertig-HVAC | L13: Follow-up 10.10. verschickt
A14: conduit architecture + design | B14: Architektur | C14: info@conduitad.com | D14: Abgeschickt | E14: 46302 | F14: =IF(OR(E14="",G14<>"",H14<>""),"",WORKDAY(E14,5)) | J14: =IF(A14="","",IF(I14<>"","Antwort bearbeiten",IF(G14<>"",IF(TODAY()>=WORKDAY(G14,7),"Als Keine Antwort abschließen","Warten auf Antwort"),IF(E14<>"",IF(TODAY()>=F14,"Follow-up schreiben!","Warten bis Follow-up-Datum"),IF(D14="Versandbereit","Erstmail senden","Konzept fertigstellen"))))) | K14: 09-Versandfertig-Architektur | L14: Follow-up liegt im Zoho-Postausgang (geplant)
A15: Peck Architects | B15: Architektur | C15: bill@peckarchitects.com | D15: Abgeschickt | E15: 46305 | F15: =IF(OR(E15="",G15<>"",H15<>""),"",WORKDAY(E15,5)) | J15: =IF(A15="","",IF(I15<>"","Antwort bearbeiten",IF(G15<>"",IF(TODAY()>=WORKDAY(G15,7),"Als Keine Antwort abschließen","Warten auf Antwort"),IF(E15<>"",IF(TODAY()>=F15,"Follow-up schreiben!","Warten bis Follow-up-Datum"),IF(D15="Versandbereit","Erstmail senden","Konzept fertigstellen"))))) | K15: 09-Versandfertig-Architektur | L15: Erstmail 10.10. verschickt (laut Zoho "Gesendet")
A16: Boothe Architects | B16: Architektur | C16: ray@boothearchitects.com | D16: Abgeschickt | E16: 46305 | F16: =IF(OR(E16="",G16<>"",H16<>""),"",WORKDAY(E16,5)) | J16: =IF(A16="","",IF(I16<>"","Antwort bearbeiten",IF(G16<>"",IF(TODAY()>=WORKDAY(G16,7),"Als Keine Antwort abschließen","Warten auf Antwort"),IF(E16<>"",IF(TODAY()>=F16,"Follow-up schreiben!","Warten bis Follow-up-Datum"),IF(D16="Versandbereit","Erstmail senden","Konzept fertigstellen"))))) | K16: 09-Versandfertig-Architektur | L16: Erstmail 10.10. verschickt (laut Zoho "Gesendet")
A17: Laurie Murphy Architect | B17: Architektur | C17: lmurphy@lmurphyarchitect.com | D17: Abgeschickt | E17: 46305 | F17: =IF(OR(E17="",G17<>"",H17<>""),"",WORKDAY(E17,5)) | J17: =IF(A17="","",IF(I17<>"","Antwort bearbeiten",IF(G17<>"",IF(TODAY()>=WORKDAY(G17,7),"Als Keine Antwort abschließen","Warten auf Antwort"),IF(E17<>"",IF(TODAY()>=F17,"Follow-up schreiben!","Warten bis Follow-up-Datum"),IF(D17="Versandbereit","Erstmail senden","Konzept fertigstellen"))))) | K17: 09-Versandfertig-Architektur | L17: Erstmail 10.10. verschickt (laut Zoho "Gesendet")
A18: Magee Architects | B18: Architektur | C18: marchitects@magee-architects.com | D18: Abgeschickt | E18: 46305 | F18: =IF(OR(E18="",G18<>"",H18<>""),"",WORKDAY(E18,5)) | J18: =IF(A18="","",IF(I18<>"","Antwort bearbeiten",IF(G18<>"",IF(TODAY()>=WORKDAY(G18,7),"Als Keine Antwort abschließen","Warten auf Antwort"),IF(E18<>"",IF(TODAY()>=F18,"Follow-up schreiben!","Warten bis Follow-up-Datum"),IF(D18="Versandbereit","Erstmail senden","Konzept fertigstellen"))))) | K18: 09-Versandfertig-Architektur | L18: Erstmail 10.10. verschickt (laut Zoho "Gesendet")
A19: Bush Architects | B19: Architektur | C19: contact@busharchitects.design | D19: Abgeschickt | E19: 46305 | F19: =IF(OR(E19="",G19<>"",H19<>""),"",WORKDAY(E19,5)) | J19: =IF(A19="","",IF(I19<>"","Antwort bearbeiten",IF(G19<>"",IF(TODAY()>=WORKDAY(G19,7),"Als Keine Antwort abschließen","Warten auf Antwort"),IF(E19<>"",IF(TODAY()>=F19,"Follow-up schreiben!","Warten bis Follow-up-Datum"),IF(D19="Versandbereit","Erstmail senden","Konzept fertigstellen"))))) | K19: 09-Versandfertig-Architektur | L19: Erstmail 10.10. verschickt (laut Zoho "Gesendet")
A20: A.GRUPPO Architects | B20: Architektur | C20: thad@agruppo.com | D20: Abgeschickt | E20: 46305 | F20: =IF(OR(E20="",G20<>"",H20<>""),"",WORKDAY(E20,5)) | J20: =IF(A20="","",IF(I20<>"","Antwort bearbeiten",IF(G20<>"",IF(TODAY()>=WORKDAY(G20,7),"Als Keine Antwort abschließen","Warten auf Antwort"),IF(E20<>"",IF(TODAY()>=F20,"Follow-up schreiben!","Warten bis Follow-up-Datum"),IF(D20="Versandbereit","Erstmail senden","Konzept fertigstellen"))))) | K20: 09-Versandfertig-Architektur | L20: Erstmail 10.10. verschickt (laut Zoho "Gesendet")
A21: Royal Flush Plumbing | B21: Klempner | C21: rfplumber@yahoo.com | D21: Abgeschickt | E21: 46304 | F21: =IF(OR(E21="",G21<>"",H21<>""),"",WORKDAY(E21,5)) | J21: =IF(A21="","",IF(I21<>"","Antwort bearbeiten",IF(G21<>"",IF(TODAY()>=WORKDAY(G21,7),"Als Keine Antwort abschließen","Warten auf Antwort"),IF(E21<>"",IF(TODAY()>=F21,"Follow-up schreiben!","Warten bis Follow-up-Datum"),IF(D21="Versandbereit","Erstmail senden","Konzept fertigstellen"))))) | K21: 10-Versandfertig-Handwerk | L21: PDF angehängt; Scroll-Video erst nach einem Ja; Follow-up liegt im Zoho-Postausgang (geplant)
A22: KPS Electric | B22: Elektriker | C22: kpselectricllc@yahoo.com | D22: Abgeschickt | E22: 46304 | F22: =IF(OR(E22="",G22<>"",H22<>""),"",WORKDAY(E22,5)) | J22: =IF(A22="","",IF(I22<>"","Antwort bearbeiten",IF(G22<>"",IF(TODAY()>=WORKDAY(G22,7),"Als Keine Antwort abschließen","Warten auf Antwort"),IF(E22<>"",IF(TODAY()>=F22,"Follow-up schreiben!","Warten bis Follow-up-Datum"),IF(D22="Versandbereit","Erstmail senden","Konzept fertigstellen"))))) | K22: 10-Versandfertig-Handwerk | L22: Erstmail am 10.10. erneut gesendet. Die alte Mail vom 09.10. liegt noch im Postausgang (Doppelversand vermeiden)
A23: Independent Overhead Doors | B23: Garagentore | C23: iodoors@sbcglobal.net | D23: Abgeschickt | E23: 46304 | F23: =IF(OR(E23="",G23<>"",H23<>""),"",WORKDAY(E23,5)) | J23: =IF(A23="","",IF(I23<>"","Antwort bearbeiten",IF(G23<>"",IF(TODAY()>=WORKDAY(G23,7),"Als Keine Antwort abschließen","Warten auf Antwort"),IF(E23<>"",IF(TODAY()>=F23,"Follow-up schreiben!","Warten bis Follow-up-Datum"),IF(D23="Versandbereit","Erstmail senden","Konzept fertigstellen"))))) | K23: 10-Versandfertig-Handwerk | L23: PDF angehängt; Scroll-Video erst nach einem Ja; Follow-up liegt im Zoho-Postausgang (geplant)
A24: Stevan Buren Roofing | B24: Dachdecker | C24: office@stevanburen.com | D24: Abgeschickt | E24: 46304 | F24: =IF(OR(E24="",G24<>"",H24<>""),"",WORKDAY(E24,5)) | J24: =IF(A24="","",IF(I24<>"","Antwort bearbeiten",IF(G24<>"",IF(TODAY()>=WORKDAY(G24,7),"Als Keine Antwort abschließen","Warten auf Antwort"),IF(E24<>"",IF(TODAY()>=F24,"Follow-up schreiben!","Warten bis Follow-up-Datum"),IF(D24="Versandbereit","Erstmail senden","Konzept fertigstellen"))))) | K24: 10-Versandfertig-Handwerk | L24: PDF angehängt; Scroll-Video erst nach einem Ja; Follow-up liegt im Zoho-Postausgang (geplant)
A25: RPGA Design Group | B25: Architektur | C25: rickgarza@rpgaarchitects.com | D25: Abgeschickt | E25: 46304 | F25: =IF(OR(E25="",G25<>"",H25<>""),"",WORKDAY(E25,5)) | J25: =IF(A25="","",IF(I25<>"","Antwort bearbeiten",IF(G25<>"",IF(TODAY()>=WORKDAY(G25,7),"Als Keine Antwort abschließen","Warten auf Antwort"),IF(E25<>"",IF(TODAY()>=F25,"Follow-up schreiben!","Warten bis Follow-up-Datum"),IF(D25="Versandbereit","Erstmail senden","Konzept fertigstellen"))))) | K25: 11-Versandfertig-Gastro-Architektur | L25: PDF angehängt; Scroll-Video erst nach einem Ja; Follow-up liegt im Zoho-Postausgang (geplant)
... A33: Burleson Dental Care | B33: Zahnarzt | C33: info@burlesondentalcare.com | D33: Abgeschickt | E33: 46304 | F33: =IF(OR(E33="",G33<>"",H33<>""),"",WORKDAY(E33,5)) | J33: =IF(A33="","",IF(I33<>"","Antwort bearbeiten",IF(G33<>"",IF(TODAY()>=WORKDAY(G33,7),"Als Keine Antwort abschließen","Warten auf Antwort"),IF(E33<>"",IF(TODAY()>=F33,"Follow-up schreiben!","Warten bis Follow-up-Datum"),IF(D33="Versandbereit","Erstmail senden","Konzept fertigstellen"))))) | K33: 12-Versandfertig-Service | L33: Erstmail 09.10. mit PDF verschickt; Follow-up liegt im Zoho-Postausgang (geplant)
A34: Chief Pest Control | B34: Schädlingsbekämpfung | C34: chiefpestmail@yahoo.com | D34: In Bearbeitung | F34: =IF(OR(E34="",G34<>"",H34<>""),"",WORKDAY(E34,5)) | J34: =IF(A34="","",IF(I34<>"","Antwort bearbeiten",IF(G34<>"",IF(TODAY()>=WORKDAY(G34,7),"Als Keine Antwort abschließen","Warten auf Antwort"),IF(E34<>"",IF(TODAY()>=F34,"Follow-up schreiben!","Warten bis Follow-up-Datum"),IF(D34="Versandbereit","Erstmail senden","Konzept fertigstellen"))))) | K34: Neue-Leads-Service-2026-10-09 | L34: Lead gefunden 09.10., Konzept offen
A35: Monkey Wrench Cycles | B35: Motorradwerkstatt | C35: FrankV@MonkeyWrenchMotorcycles.com | D35: Abgeschickt | E35: 46305 | F35: =IF(OR(E35="",G35<>"",H35<>""),"",WORKDAY(E35,5)) | J35: =IF(A35="","",IF(I35<>"","Antwort bearbeiten",IF(G35<>"",IF(TODAY()>=WORKDAY(G35,7),"Als Keine Antwort abschließen","Warten auf Antwort"),IF(E35<>"",IF(TODAY()>=F35,"Follow-up schreiben!","Warten bis Follow-up-Datum"),IF(D35="Versandbereit","Erstmail senden","Konzept fertigstellen"))))) | K35: 13-Versandfertig-Mix | L35: Erstmail 10.10. mit PDF verschickt; Follow-up liegt im Zoho-Postausgang (geplant)
A36: Factory Finish Auto Collision Center | B36: Karosseriewerkstatt | C36: factoryfinishpb@sbcglobal.net | D36: Abgeschickt | E36: 46305 | F36: =IF(OR(E36="",G36<>"",H36<>""),"",WORKDAY(E36,5)) | J36: =IF(A36="","",IF(I36<>"","Antwort bearbeiten",IF(G36<>"",IF(TODAY()>=WORKDAY(G36,7),"Als Keine Antwort abschließen","Warten auf Antwort"),IF(E36<>"",IF(TODAY()>=F36,"Follow-up schreiben!","Warten bis Follow-up-Datum"),IF(D36="Versandbereit","Erstmail senden","Konzept fertigstellen"))))) | K36: 13-Versandfertig-Mix | L36: Erstmail 10.10. mit PDF verschickt; Follow-up liegt im Zoho-Postausgang (geplant)
A37: Kite's Custom Cleaners | B37: Reinigung | C37: info@kitescleaners.com | D37: Abgeschickt | E37: 46305 | F37: =IF(OR(E37="",G37<>"",H37<>""),"",WORKDAY(E37,5)) | J37: =IF(A37="","",IF(I37<>"","Antwort bearbeiten",IF(G37<>"",IF(TODAY()>=WORKDAY(G37,7),"Als Keine Antwort abschließen","Warten auf Antwort"),IF(E37<>"",IF(TODAY()>=F37,"Follow-up schreiben!","Warten bis Follow-up-Datum"),IF(D37="Versandbereit","Erstmail senden","Konzept fertigstellen"))))) | K37: 13-Versandfertig-Mix | L37: Erstmail 10.10. mit PDF verschickt; Follow-up liegt im Zoho-Postausgang (geplant)
A38: Studio of MoveMINT | B38: Tanzschule | C38: info@studioofmovemint.com | D38: Abgeschickt | E38: 46305 | F38: =IF(OR(E38="",G38<>"",H38<>""),"",WORKDAY(E38,5)) | J38: =IF(A38="","",IF(I38<>"","Antwort bearbeiten",IF(G38<>"",IF(TODAY()>=WORKDAY(G38,7),"Als Keine Antwort abschließen","Warten auf Antwort"),IF(E38<>"",IF(TODAY()>=F38,"Follow-up schreiben!","Warten bis Follow-up-Datum"),IF(D38="Versandbereit","Erstmail senden","Konzept fertigstellen"))))) | K38: 13-Versandfertig-Mix | L38: Erstmail 10.10. mit PDF verschickt; Follow-up liegt im Zoho-Postausgang (geplant)
A39: Arlington Natural Wellness Center | B39: Chiropraktik | C39: arlingtonnwc@yahoo.com | D39: Abgeschickt | E39: 46305 | F39: =IF(OR(E39="",G39<>"",H39<>""),"",WORKDAY(E39,5)) | J39: =IF(A39="","",IF(I39<>"","Antwort bearbeiten",IF(G39<>"",IF(TODAY()>=WORKDAY(G39,7),"Als Keine Antwort abschließen","Warten auf Antwort"),IF(E39<>"",IF(TODAY()>=F39,"Follow-up schreiben!","Warten bis Follow-up-Datum"),IF(D39="Versandbereit","Erstmail senden","Konzept fertigstellen"))))) | K39: 13-Versandfertig-Mix | L39: Erstmail 10.10. mit PDF verschickt; Follow-up liegt im Zoho-Postausgang (geplant)
A40: J.A.C. Welding & Fabrication | B40: Schweißerei | C40: jacwelding@sbcglobal.net | D40: Abgeschickt | E40: 46305 | F40: =IF(OR(E40="",G40<>"",H40<>""),"",WORKDAY(E40,5)) | J40: =IF(A40="","",IF(I40<>"","Antwort bearbeiten",IF(G40<>"",IF(TODAY()>=WORKDAY(G40,7),"Als Keine Antwort abschließen","Warten auf Antwort"),IF(E40<>"",IF(TODAY()>=F40,"Follow-up schreiben!","Warten bis Follow-up-Datum"),IF(D40="Versandbereit","Erstmail senden","Konzept fertigstellen"))))) | K40: 14-Versandfertig-Gewerbe | L40: Erstmail 10.10. verschickt (laut Zoho "Gesendet")
A41: Accurate-Tune (Andy White) | B41: Klavierstimmer | C41: andywhite@accurate-tune.com | D41: Abgeschickt | E41: 46305 | F41: =IF(OR(E41="",G41<>"",H41<>""),"",WORKDAY(E41,5)) | J41: =IF(A41="","",IF(I41<>"","Antwort bearbeiten",IF(G41<>"",IF(TODAY()>=WORKDAY(G41,7),"Als Keine Antwort abschließen","Warten auf Antwort"),IF(E41<>"",IF(TODAY()>=F41,"Follow-up schreiben!","Warten bis Follow-up-Datum"),IF(D41="Versandbereit","Erstmail senden","Konzept fertigstellen"))))) | K41: 14-Versandfertig-Gewerbe | L41: Erstmail 10.10. verschickt (laut Zoho "Gesendet")
A42: GSI Geomatic Solutions | B42: Landvermessung | C42: shelby@gsisurvey.com | D42: Abgeschickt | E42: 46305 | F42: =IF(OR(E42="",G42<>"",H42<>""),"",WORKDAY(E42,5)) | J42: =IF(A42="","",IF(I42<>"","Antwort bearbeiten",IF(G42<>"",IF(TODAY()>=WORKDAY(G42,7),"Als Keine Antwort abschließen","Warten auf Antwort"),IF(E42<>"",IF(TODAY()>=F42,"Follow-up schreiben!","Warten bis Follow-up-Datum"),IF(D42="Versandbereit","Erstmail senden","Konzept fertigstellen"))))) | K42: 14-Versandfertig-Gewerbe | L42: Erstmail 10.10. verschickt (laut Zoho "Gesendet")
A43: Armor Texas Insurance Agency | B43: Versicherung | C43: hedy@armortexasins.com | D43: Abgeschickt | E43: 46305 | F43: =IF(OR(E43="",G43<>"",H43<>""),"",WORKDAY(E43,5)) | J43: =IF(A43="","",IF(I43<>"","Antwort bearbeiten",IF(G43<>"",IF(TODAY()>=WORKDAY(G43,7),"Als Keine Antwort abschließen","Warten auf Antwort"),IF(E43<>"",IF(TODAY()>=F43,"Follow-up schreiben!","Warten bis Follow-up-Datum"),IF(D43="Versandbereit","Erstmail senden","Konzept fertigstellen"))))) | K43: 14-Versandfertig-Gewerbe | L43: Erstmail 10.10. verschickt (laut Zoho "Gesendet")
A44: Manjula P. Modi, CPA PLLC | B44: Steuerberater | C44: info@fort-worth-cpa.com | D44: Abgeschickt | E44: 46305 | F44: =IF(OR(E44="",G44<>"",H44<>""),"",WORKDAY(E44,5)) | J44: =IF(A44="","",IF(I44<>"","Antwort bearbeiten",IF(G44<>"",IF(TODAY()>=WORKDAY(G44,7),"Als Keine Antwort abschließen","Warten auf Antwort"),IF(E44<>"",IF(TODAY()>=F44,"Follow-up schreiben!","Warten bis Follow-up-Datum"),IF(D44="Versandbereit","Erstmail senden","Konzept fertigstellen"))))) | K44: 14-Versandfertig-Gewerbe | L44: Erstmail 10.10. verschickt (laut Zoho "Gesendet")
A45: Funky Town Donuts | B45: Donut-Bäckerei | C45: orders@funkytowndonuts.com | D45: Versandbereit | F45: =IF(OR(E45="",G45<>"",H45<>""),"",WORKDAY(E45,5)) | J45: =IF(A45="","",IF(I45<>"","Antwort bearbeiten",IF(G45<>"",IF(TODAY()>=WORKDAY(G45,7),"Als Keine Antwort abschließen","Warten auf Antwort"),IF(E45<>"",IF(TODAY()>=F45,"Follow-up schreiben!","Warten bis Follow-up-Datum"),IF(D45="Versandbereit","Erstmail senden","Konzept fertigstellen"))))) | K45: 15-Versandfertig-Laden | L45: Konzeptseite, PDF, Video und Mail fertig 10.10., versandbereit
A46: Michael's PC Sales & Service | B46: Computer-Service | C46: info@michaelspcsalesandservice.com | D46: Versandbereit | F46: =IF(OR(E46="",G46<>"",H46<>""),"",WORKDAY(E46,5)) | J46: =IF(A46="","",IF(I46<>"","Antwort bearbeiten",IF(G46<>"",IF(TODAY()>=WORKDAY(G46,7),"Als Keine Antwort abschließen","Warten auf Antwort"),IF(E46<>"",IF(TODAY()>=F46,"Follow-up schreiben!","Warten bis Follow-up-Datum"),IF(D46="Versandbereit","Erstmail senden","Konzept fertigstellen"))))) | K46: 15-Versandfertig-Laden | L46: Konzeptseite, PDF, Video und Mail fertig 10.10., versandbereit
A47: Helga's Custom Alterations | B47: Änderungsschneiderei | C47: info@helgasalterations.com | D47: Versandbereit | F47: =IF(OR(E47="",G47<>"",H47<>""),"",WORKDAY(E47,5)) | J47: =IF(A47="","",IF(I47<>"","Antwort bearbeiten",IF(G47<>"",IF(TODAY()>=WORKDAY(G47,7),"Als Keine Antwort abschließen","Warten auf Antwort"),IF(E47<>"",IF(TODAY()>=F47,"Follow-up schreiben!","Warten bis Follow-up-Datum"),IF(D47="Versandbereit","Erstmail senden","Konzept fertigstellen"))))) | K47: 15-Versandfertig-Laden | L47: Konzeptseite, PDF, Video und Mail fertig 10.10., versandbereit
...

Sheet Übersicht
A1: Akquise-Übersicht
A2: Rechnet sich aus dem Blatt „Tracker“. Hier nichts eintragen.
A4: Firmen im Tracker | B4: =COUNTA(Tracker!$A$2:$A$200)
A5: Erstmails gesendet | B5: =COUNT(Tracker!$E$2:$E$200)
A6: Follow-ups gesendet | B6: =COUNT(Tracker!$G$2:$G$200)
A7: Antworten | B7: =COUNTA(Tracker!$I$2:$I$200)
A8: Antwortquote | B8: =IFERROR(B7/B5,0)
A9: Follow-ups jetzt fällig | B9: =SUMPRODUCT(--ISNUMBER(Tracker!$F$2:$F$200),--(Tracker!$F$2:$F$200<=TODAY()))
A11: Status | B11: Anzahl
A12: In Bearbeitung | B12: =COUNTIF(Tracker!$D$2:$D$200,A12)
A13: Versandbereit | B13: =COUNTIF(Tracker!$D$2:$D$200,A13)
A14: Abgeschickt | B14: =COUNTIF(Tracker!$D$2:$D$200,A14)
A15: Follow-up gesendet | B15: =COUNTIF(Tracker!$D$2:$D$200,A15)
A16: Antwort erhalten | B16: =COUNTIF(Tracker!$D$2:$D$200,A16)
A17: Keine Antwort | B17: =COUNTIF(Tracker!$D$2:$D$200,A17)
A18: Kein Interesse | B18: =COUNTIF(Tracker!$D$2:$D$200,A18)
A19: Kunde | B19: =COUNTIF(Tracker!$D$2:$D$200,A19)
A22: Nische | B22: Gesendet | C22: Antworten | D22: Antwortquote
A23: Architektur | B23: =COUNTIFS(Tracker!$B$2:$B$200,A23,Tracker!$E$2:$E$200,">0") | C23: =COUNTIFS(Tracker!$B$2:$B$200,A23,Tracker!$I$2:$I$200,"<>") | D23: =IFERROR(C23/B23,0)
A24: Baumpflege | B24: =COUNTIFS(Tracker!$B$2:$B$200,A24,Tracker!$E$2:$E$200,">0") | C24: =COUNTIFS(Tracker!$B$2:$B$200,A24,Tracker!$I$2:$I$200,"<>") | D24: =IFERROR(C24/B24,0)
A25: Dachdecker | B25: =COUNTIFS(Tracker!$B$2:$B$200,A25,Tracker!$E$2:$E$200,">0") | C25: =COUNTIFS(Tracker!$B$2:$B$200,A25,Tracker!$I$2:$I$200,"<>") | D25: =IFERROR(C25/B25,0)
A26: Elektriker | B26: =COUNTIFS(Tracker!$B$2:$B$200,A26,Tracker!$E$2:$E$200,">0") | C26: =COUNTIFS(Tracker!$B$2:$B$200,A26,Tracker!$I$2:$I$200,"<>") | D26: =IFERROR(C26/B26,0)
A27: Fundament | B27: =COUNTIFS(Tracker!$B$2:$B$200,A27,Tracker!$E$2:$E$200,">0") | C27: =COUNTIFS(Tracker!$B$2:$B$200,A27,Tracker!$I$2:$I$200,"<>") | D27: =IFERROR(C27/B27,0)
A28: Garagentore | B28: =COUNTIFS(Tracker!$B$2:$B$200,A28,Tracker!$E$2:$E$200,">0") | C28: =COUNTIFS(Tracker!$B$2:$B$200,A28,Tracker!$I$2:$I$200,"<>") | D28: =IFERROR(C28/B28,0)
A29: HVAC | B29: =COUNTIFS(Tracker!$B$2:$B$200,A29,Tracker!$E$2:$E$200,">0") | C29: =COUNTIFS(Tracker!$B$2:$B$200,A29,Tracker!$I$2:$I$200,"<>") | D29: =IFERROR(C29/B29,0)
A30: Klempner | B30: =COUNTIFS(Tracker!$B$2:$B$200,A30,Tracker!$E$2:$E$200,">0") | C30: =COUNTIFS(Tracker!$B$2:$B$200,A30,Tracker!$I$2:$I$200,"<>") | D30: =IFERROR(C30/B30,0)
A31: Pool | B31: =COUNTIFS(Tracker!$B$2:$B$200,A31,Tracker!$E$2:$E$200,">0") | C31: =COUNTIFS(Tracker!$B$2:$B$200,A31,Tracker!$I$2:$I$200,"<>") | D31: =IFERROR(C31/B31,0)
A32: Zaun & Terrasse | B32: =COUNTIFS(Tracker!$B$2:$B$200,A32,Tracker!$E$2:$E$200,">0") | C32: =COUNTIFS(Tracker!$B$2:$B$200,A32,Tracker!$I$2:$I$200,"<>") | D32: =IFERROR(C32/B32,0)
A35: So benutzt du den Tracker
A36: 1. Mail verschickt: Datum in „Erstmail am“ eintragen, Status auf „Abgeschickt“. „Follow-up fällig“ rechnet sich selbst (5 Werktage später) und wird rot, sobald es fällig ist.
A37: 2. Follow-up verschickt: Datum in „Follow-up gesendet am“, Status auf „Follow-up gesendet“. Kommt 7 Werktage danach nichts, schlägt „Nächster Schritt“ vor, den Lead als „Keine Antwort“ abzuschließen.
A38: 3. Antwort da: Datum in „Antwort am“, Art in „Antwort“ (Interessiert, Rückfrage, Kein Interesse), Status anpassen. Bei „no thanks“ sofort stoppen.
A39: 4. Neue Leads einfach unten anhängen: Formeln und Auswahllisten gehen bis Zeile 200.
A40: Stand der Versanddaten: Gesendet-Ordner von hello@northframesites.com am 09.10.2026, bis dahin keine Antworten im Postfach.
